<?xml version="1.0" encoding="utf-8"?>
<!-- This URDF was automatically created by SolidWorks to URDF Exporter! Originally created by Stephen Brawner (brawner@gmail.com) 
     Commit Version: 1.6.0-4-g7f85cfe  Build Version: 1.6.7995.38578
     For more information, please see http://wiki.ros.org/sw_urdf_exporter -->
<robot
  name="s500_uav_with_propeller">
  <link
    name="base_link">
    <inertial>
      <origin
        xyz="-3.9741E-05 -2.1279E-05 -0.02127"
        rpy="0 0 0" />
      <mass
        value="0.57121" />
      <inertia
        ixx="0.00042201"
        ixy="-2.0445E-06"
        ixz="-1.0225E-06"
        iyy="0.00073654"
        iyz="6.0809E-08"
        izz="0.0010532" />
    </inertial>
    <visual>
      <origin
        xyz="0 0 0"
        rpy="0 0 0" />
      <geometry>
        <mesh
          filename="package://s500_uav_with_propeller/meshes/base_link.STL" />
      </geometry>
      <material
        name="">
        <color
          rgba="0.75294 0.75294 0.75294 1" />
      </material>
    </visual>
    <collision>
      <origin
        xyz="0 0 0"
        rpy="0 0 0" />
      <geometry>
        <mesh
          filename="package://s500_uav_with_propeller/meshes/base_link.STL" />
      </geometry>
    </collision>
  </link>
  <link
    name="link_1">
    <inertial>
      <origin
        xyz="-5.7462E-12 -0.00019643 -0.076809"
        rpy="0 0 0" />
      <mass
        value="0.056776" />
      <inertia
        ixx="1.5689E-05"
        ixy="-1.0156E-16"
        ixz="-5.2427E-15"
        iyy="1.3617E-05"
        iyz="-1.6017E-09"
        izz="8.7857E-06" />
    </inertial>
    <visual>
      <origin
        xyz="0 0 0"
        rpy="0 0 0" />
      <geometry>
        <mesh
          filename="package://s500_uav_with_propeller/meshes/link_1.STL" />
      </geometry>
      <material
        name="">
        <color
          rgba="1 1 1 1" />
      </material>
    </visual>
    <collision>
      <origin
        xyz="0 0 0"
        rpy="0 0 0" />
      <geometry>
        <mesh
          filename="package://s500_uav_with_propeller/meshes/link_1.STL" />
      </geometry>
    </collision>
  </link>
  <joint
    name="joint_1"
    type="continuous">
    <origin
      xyz="0.0007 0 -0.07275"
      rpy="0 1.2222 0" />
    <parent
      link="base_link" />
    <child
      link="link_1" />
    <axis
      xyz="0 1 0" />
  </joint>
  <link
    name="link_2">
    <inertial>
      <origin
        xyz="0.000575394854711864 0.000246505418719023 -0.0722608850455854"
        rpy="0 0 0" />
      <mass
        value="0.0656630050112662" />
      <inertia
        ixx="1.30057574621575E-05"
        ixy="2.55528503526128E-07"
        ixz="4.40822710632907E-09"
        iyy="1.49846467170001E-05"
        iyz="-6.07773891098389E-07"
        izz="1.60537315409108E-05" />
    </inertial>
    <visual>
      <origin
        xyz="0 0 0"
        rpy="0 0 0" />
      <geometry>
        <mesh
          filename="package://s500_uav_with_propeller/meshes/link_2.STL" />
      </geometry>
      <material
        name="">
        <color
          rgba="1 1 1 1" />
      </material>
    </visual>
    <collision>
      <origin
        xyz="0 0 0"
        rpy="0 0 0" />
      <geometry>
        <mesh
          filename="package://s500_uav_with_propeller/meshes/link_2.STL" />
      </geometry>
    </collision>
  </link>
  <joint
    name="joint_2"
    type="continuous">
    <origin
      xyz="0 0 -0.0992499999999631"
      rpy="0 0.293604338073927 0" />
    <parent
      link="link_1" />
    <child
      link="link_2" />
    <axis
      xyz="0 1 0" />
  </joint>
  <link
    name="link_3">
    <inertial>
      <origin
        xyz="0.025274 0.000991 -0.041284"
        rpy="0 0 0" />
      <mass
        value="0.012158" />
      <inertia
        ixx="1.0667E-05"
        ixy="-2.5213E-09"
        ixz="3.6553E-06"
        iyy="1.2675E-05"
        iyz="4.2721E-09"
        izz="2.4775E-06" />
    </inertial>
    <visual>
      <origin
        xyz="0 0 0"
        rpy="0 0 0" />
      <geometry>
        <mesh
          filename="package://s500_uav_with_propeller/meshes/link_3.STL" />
      </geometry>
      <material
        name="">
        <color
          rgba="0.92157 0.92157 0.92157 1" />
      </material>
    </visual>
    <collision>
      <origin
        xyz="0 0 0"
        rpy="0 0 0" />
      <geometry>
        <mesh
          filename="package://s500_uav_with_propeller/meshes/link_3.STL" />
      </geometry>
    </collision>
  </link>
  <joint
    name="joint_3"
    type="continuous">
    <origin
      xyz="-0.0110000000001107 0 -0.0822500000000793"
      rpy="0 0.234319548568971 3.14159265358978" />
    <parent
      link="link_2" />
    <child
      link="link_3" />
    <axis
      xyz="0 1 0" />
  </joint>
  <link
    name="link_4">
    <inertial>
      <origin
        xyz="0.024422 -0.0009913 -0.039818"
        rpy="0 0 0" />
      <mass
        value="0.012587" />
      <inertia
        ixx="1.1294E-05"
        ixy="2.4212E-09"
        ixz="4.0228E-06"
        iyy="1.352E-05"
        iyz="-4.1022E-09"
        izz="2.6966E-06" />
    </inertial>
    <visual>
      <origin
        xyz="0 0 0"
        rpy="0 0 0" />
      <geometry>
        <mesh
          filename="package://s500_uav_with_propeller/meshes/link_4.STL" />
      </geometry>
      <material
        name="">
        <color
          rgba="0.92157 0.92157 0.92157 1" />
      </material>
    </visual>
    <collision>
      <origin
        xyz="0 0 0"
        rpy="0 0 0" />
      <geometry>
        <mesh
          filename="package://s500_uav_with_propeller/meshes/link_4.STL" />
      </geometry>
    </collision>
  </link>
  <joint
    name="joint_4"
    type="continuous">
    <origin
      xyz="0.0109999999998656 0 -0.0822500000001005"
      rpy="0 0.262371590022443 0" />
    <parent
      link="link_2" />
    <child
      link="link_4" />
    <axis
      xyz="0 1 0" />
  </joint>
  <link
    name="rotor_1">
    <inertial>
      <origin
        xyz="9.324E-09 -0.020263 -1.4817E-05"
        rpy="0 0 0" />
      <mass
        value="0.010198" />
      <inertia
        ixx="3.3719E-05"
        ixy="1.1138E-12"
        ixz="-4.3242E-07"
        iyy="3.3919E-05"
        iyz="-3.8084E-11"
        izz="2.8343E-07" />
    </inertial>
    <visual>
      <origin
        xyz="0 0 0"
        rpy="0 0 0" />
      <geometry>
        <mesh
          filename="package://s500_uav_with_propeller/meshes/rotor_1.STL" />
      </geometry>
      <material
        name="">
        <color
          rgba="0.79216 0.81961 0.93333 1" />
      </material>
    </visual>
    <collision>
      <origin
        xyz="0 0 0"
        rpy="0 0 0" />
      <geometry>
        <mesh
          filename="package://s500_uav_with_propeller/meshes/rotor_1.STL" />
      </geometry>
    </collision>
  </link>
  <joint
    name="rotor_joint_1"
    type="continuous">
    <origin
      xyz="-0.17083 -0.17083 0.048368"
      rpy="-1.5059 0.058341 1.6252" />
    <parent
      link="base_link" />
    <child
      link="rotor_1" />
    <axis
      xyz="0 1 0" />
  </joint>
  <link
    name="rotor_2">
    <inertial>
      <origin
        xyz="1.0388E-07 0.0091876 -1.3792E-05"
        rpy="0 0 0" />
      <mass
        value="0.010198" />
      <inertia
        ixx="3.3719E-05"
        ixy="-1.0939E-12"
        ixz="-4.3247E-07"
        iyy="3.3919E-05"
        iyz="-6.8224E-11"
        izz="2.8343E-07" />
    </inertial>
    <visual>
      <origin
        xyz="0 0 0"
        rpy="0 0 0" />
      <geometry>
        <mesh
          filename="package://s500_uav_with_propeller/meshes/rotor_2.STL" />
      </geometry>
      <material
        name="">
        <color
          rgba="0.79216 0.81961 0.93333 1" />
      </material>
    </visual>
    <collision>
      <origin
        xyz="0 0 0"
        rpy="0 0 0" />
      <geometry>
        <mesh
          filename="package://s500_uav_with_propeller/meshes/rotor_2.STL" />
      </geometry>
    </collision>
  </link>
  <joint
    name="rotor_joint_2"
    type="continuous">
    <origin
      xyz="0.17009 -0.17009 0.060457"
      rpy="1.5037 0.055795 1.4778" />
    <parent
      link="base_link" />
    <child
      link="rotor_2" />
    <axis
      xyz="0 1 0" />
  </joint>
  <link
    name="rotor_3">
    <inertial>
      <origin
        xyz="1.0251E-07 -0.0074274 -1.368E-05"
        rpy="0 0 0" />
      <mass
        value="0.010198" />
      <inertia
        ixx="3.372E-05"
        ixy="-8.2454E-13"
        ixz="-4.3251E-07"
        iyy="3.3919E-05"
        iyz="-7.0007E-11"
        izz="2.8344E-07" />
    </inertial>
    <visual>
      <origin
        xyz="0 0 0"
        rpy="0 0 0" />
      <geometry>
        <mesh
          filename="package://s500_uav_with_propeller/meshes/rotor_3.STL" />
      </geometry>
      <material
        name="">
        <color
          rgba="0.79216 0.81961 0.93333 1" />
      </material>
    </visual>
    <collision>
      <origin
        xyz="0 0 0"
        rpy="0 0 0" />
      <geometry>
        <mesh
          filename="package://s500_uav_with_propeller/meshes/rotor_3.STL" />
      </geometry>
    </collision>
  </link>
  <joint
    name="rotor_joint_3"
    type="continuous">
    <origin
      xyz="0.17004 0.17004 0.061155"
      rpy="-1.6359 -0.058179 1.6277" />
    <parent
      link="base_link" />
    <child
      link="rotor_3" />
    <axis
      xyz="0 1 0" />
  </joint>
  <link
    name="rotor_4">
    <inertial>
      <origin
        xyz="9.5977E-09 0.028014 -1.4819E-05"
        rpy="0 0 0" />
      <mass
        value="0.010198" />
      <inertia
        ixx="3.3719E-05"
        ixy="1.1168E-12"
        ixz="-4.3242E-07"
        iyy="3.3919E-05"
        iyz="-3.8057E-11"
        izz="2.8343E-07" />
    </inertial>
    <visual>
      <origin
        xyz="0 0 0"
        rpy="0 0 0" />
      <geometry>
        <mesh
          filename="package://s500_uav_with_propeller/meshes/rotor_4.STL" />
      </geometry>
      <material
        name="">
        <color
          rgba="0.79216 0.81961 0.93333 1" />
      </material>
    </visual>
    <collision>
      <origin
        xyz="0 0 0"
        rpy="0 0 0" />
      <geometry>
        <mesh
          filename="package://s500_uav_with_propeller/meshes/rotor_4.STL" />
      </geometry>
    </collision>
  </link>
  <joint
    name="rotor_joint_4"
    type="continuous">
    <origin
      xyz="-0.17125 0.17125 0.041703"
      rpy="1.6359 -0.058101 1.5127" />
    <parent
      link="base_link" />
    <child
      link="rotor_4" />
    <axis
      xyz="0 1 0" />
  </joint>
</robot>